Workbook
Name Slicer_Overall: #N/A

Sheet Overall
B2: Lab Not Completed Count | C2: Completion Count
A3: Row Labels | B3: Sum of Overall | C3: Sum of Completed Count
A4: Eswari M | B4: 8 | C4: 1
A5: Mohamed Sathik Z | B5: 8 | C5: 1
A6: Sanjai P | B6: 8 | C6: 1
A7: Vikram G | B7: 8 | C7: 1
A8: Grand Total | B8: 32 | C8: 4

Sheet Overall Lab
A1: Student Code | B1: Student Name | C1: Email ID | D1: Mobile No. | E1: Attendance | F1: LAB1 | G1: LAB2 | H1: LAB3 | I1: LAB4 | J1: LAB5 | K1: LAB6 | L1: LAB7 | M1: LAB8 | N1: LAB9 | O1: Completed Count | P1: Overall
A2: AF05308119 | B2: Keerthikraj J | C2: jpkeerthik30@gmail.com | D2: 9789410647 | E2: 66 | F2: =_xlfn.XLOOKUP(A2,'Lab-1'!A:A,'Lab-1'!G:G,"Not Completed") -> 100 | G2: =_xlfn.XLOOKUP(A2,'Lab-2'!A:A,'Lab-2'!H:H,"Not Completed") -> 97 | H2: =_xlfn.XLOOKUP(A2,'Lab-3'!A:A,'Lab-3'!H:H,"Not Completed") -> 95 | I2: =_xlfn.XLOOKUP(A2,'Lab-4'!A:A,'Lab-4'!H:H,"Not Completed") -> 90 | J2: =_xlfn.XLOOKUP(A2,'Lab-5'!A:A,'Lab-5'!H:H,"Not Completed") -> 95 | K2: =_xlfn.XLOOKUP(A2,'Lab-6'!A:A,'Lab-6'!G:G,"Not Completed") -> 100 | L2: =_xlfn.XLOOKUP(A2,'Lab-7'!A:A,'Lab-7'!H:H,"Not Completed") -> 90 | M2: =_xlfn.XLOOKUP(A2,'Lab-8'!A:A,'Lab-8'!H:H,"Not Completed") -> 95 | N2: =_xlfn.XLOOKUP(A2,'Lab-9'!A:A,'Lab-9'!H:H,"Not Completed") -> Not Completed | O2: =COUNT(F2:N2) -> 8 | P2: =COUNTIF(F2:N2,"Not Completed") -> 1
A3: AF05308156 | B3: Gowtham S | C3: gowthams2k20@gmail.com | D3: 8825487437 | E3: 89 | F3: =_xlfn.XLOOKUP(A3,'Lab-1'!A:A,'Lab-1'!G:G,"Not Completed") -> 100 | G3: =_xlfn.XLOOKUP(A3,'Lab-2'!A:A,'Lab-2'!H:H,"Not Completed") -> 98 | H3: =_xlfn.XLOOKUP(A3,'Lab-3'!A:A,'Lab-3'!H:H,"Not Completed") -> 95 | I3: =_xlfn.XLOOKUP(A3,'Lab-4'!A:A,'Lab-4'!H:H,"Not Completed") -> 95 | J3: =_xlfn.XLOOKUP(A3,'Lab-5'!A:A,'Lab-5'!H:H,"Not Completed") -> 95 | K3: =_xlfn.XLOOKUP(A3,'Lab-6'!A:A,'Lab-6'!G:G,"Not Completed") -> 100 | L3: =_xlfn.XLOOKUP(A3,'Lab-7'!A:A,'Lab-7'!H:H,"Not Completed") -> 95 | M3: =_xlfn.XLOOKUP(A3,'Lab-8'!A:A,'Lab-8'!H:H,"Not Completed") -> 95 | N3: =_xlfn.XLOOKUP(A3,'Lab-9'!A:A,'Lab-9'!H:H,"Not Completed") -> 90 | O3: =COUNT(F3:N3) -> 9 | P3: =COUNTIF(F3:N3,"Not Completed") -> 0
A4: AF05308353 | B4: Varshini A S | C4: varshinivela2309@gmail.com | D4: 9361354702 | E4: 80 | F4: =_xlfn.XLOOKUP(A4,'Lab-1'!A:A,'Lab-1'!G:G,"Not Completed") -> 100 | G4: =_xlfn.XLOOKUP(A4,'Lab-2'!A:A,'Lab-2'!H:H,"Not Completed") -> 95 | H4: =_xlfn.XLOOKUP(A4,'Lab-3'!A:A,'Lab-3'!H:H,"Not Completed") -> 95 | I4: =_xlfn.XLOOKUP(A4,'Lab-4'!A:A,'Lab-4'!H:H,"Not Completed") -> 0 | J4: =_xlfn.XLOOKUP(A4,'Lab-5'!A:A,'Lab-5'!H:H,"Not Completed") -> 95 | K4: =_xlfn.XLOOKUP(A4,'Lab-6'!A:A,'Lab-6'!G:G,"Not Completed") -> 100 | L4: =_xlfn.XLOOKUP(A4,'Lab-7'!A:A,'Lab-7'!H:H,"Not Completed") -> 96 | M4: =_xlfn.XLOOKUP(A4,'Lab-8'!A:A,'Lab-8'!H:H,"Not Completed") -> 95 | N4: =_xlfn.XLOOKUP(A4,'Lab-9'!A:A,'Lab-9'!H:H,"Not Completed") -> 95 | O4: =COUNT(F4:N4) -> 9 | P4: =COUNTIF(F4:N4,"Not Completed") -> 0
A5: AF05308357 | B5: Syed Sarferaz Sajid A | C5: sarferazsajid77@gmail.com | D5: 6380927613 | E5: 94 | F5: =_xlfn.XLOOKUP(A5,'Lab-1'!A:A,'Lab-1'!G:G,"Not Completed") -> 100 | G5: =_xlfn.XLOOKUP(A5,'Lab-2'!A:A,'Lab-2'!H:H,"Not Completed") -> 98 | H5: =_xlfn.XLOOKUP(A5,'Lab-3'!A:A,'Lab-3'!H:H,"Not Completed") -> 96 | I5: =_xlfn.XLOOKUP(A5,'Lab-4'!A:A,'Lab-4'!H:H,"Not Completed") -> 90 | J5: =_xlfn.XLOOKUP(A5,'Lab-5'!A:A,'Lab-5'!H:H,"Not Completed") -> 95 | K5: =_xlfn.XLOOKUP(A5,'Lab-6'!A:A,'Lab-6'!G:G,"Not Completed") -> 100 | L5: =_xlfn.XLOOKUP(A5,'Lab-7'!A:A,'Lab-7'!H:H,"Not Completed") -> 94 | M5: =_xlfn.XLOOKUP(A5,'Lab-8'!A:A,'Lab-8'!H:H,"Not Completed") -> 95 | N5: =_xlfn.XLOOKUP(A5,'Lab-9'!A:A,'Lab-9'!H:H,"Not Completed") -> 90 | O5: =COUNT(F5:N5) -> 9 | P5: =COUNTIF(F5:N5,"Not Completed") -> 0
A6: AF05308359 | B6: Sasidharan A | C6: sasidh9198@gmail.com | D6: 9361419198 | E6: 92 | F6: =_xlfn.XLOOKUP(A6,'Lab-1'!A:A,'Lab-1'!G:G,"Not Completed") -> 100 | G6: =_xlfn.XLOOKUP(A6,'Lab-2'!A:A,'Lab-2'!H:H,"Not Completed") -> 96 | H6: =_xlfn.XLOOKUP(A6,'Lab-3'!A:A,'Lab-3'!H:H,"Not Completed") -> 95 | I6: =_xlfn.XLOOKUP(A6,'Lab-4'!A:A,'Lab-4'!H:H,"Not Completed") -> 95 | J6: =_xlfn.XLOOKUP(A6,'Lab-5'!A:A,'Lab-5'!H:H,"Not Completed") -> 95 | K6: =_xlfn.XLOOKUP(A6,'Lab-6'!A:A,'Lab-6'!G:G,"Not Completed") -> 100 | L6: =_xlfn.XLOOKUP(A6,'Lab-7'!A:A,'Lab-7'!H:H,"Not Completed") -> 95 | M6: =_xlfn.XLOOKUP(A6,'Lab-8'!A:A,'Lab-8'!H:H,"Not Completed") -> 95 | N6: =_xlfn.XLOOKUP(A6,'Lab-9'!A:A,'Lab-9'!H:H,"Not Completed") -> 95 | O6: =COUNT(F6:N6) -> 9 | P6: =COUNTIF(F6:N6,"Not Completed") -> 0
A7: AF05308374 | B7: Lakshmikanthan G | C7: lakshug999@gmail.com | D7: 9360237456 | E7: 75 | F7: =_xlfn.XLOOKUP(A7,'Lab-1'!A:A,'Lab-1'!G:G,"Not Completed") -> 100 | G7: =_xlfn.XLOOKUP(A7,'Lab-2'!A:A,'Lab-2'!H:H,"Not Completed") -> 95 | H7: =_xlfn.XLOOKUP(A7,'Lab-3'!A:A,'Lab-3'!H:H,"Not Completed") -> 90 | I7: =_xlfn.XLOOKUP(A7,'Lab-4'!A:A,'Lab-4'!H:H,"Not Completed") -> 90 | J7: =_xlfn.XLOOKUP(A7,'Lab-5'!A:A,'Lab-5'!H:H,"Not Completed") -> 95 | K7: =_xlfn.XLOOKUP(A7,'Lab-6'!A:A,'Lab-6'!G:G,"Not Completed") -> 100 | L7: =_xlfn.XLOOKUP(A7,'Lab-7'!A:A,'Lab-7'!H:H,"Not Completed") -> 80 | M7: =_xlfn.XLOOKUP(A7,'Lab-8'!A:A,'Lab-8'!H:H,"Not Completed") -> 95 | N7: =_xlfn.XLOOKUP(A7,'Lab-9'!A:A,'Lab-9'!H:H,"Not Completed") -> Not Completed | O7: =COUNT(F7:N7) -> 8 | P7: =COUNTIF(F7:N7,"Not Completed") -> 1
A8: AF05308376 | B8: Satheesh Kumar G | C8: satheeshkumar14796@gmail.com | D8: 9751234634 | E8: 85 | F8: =_xlfn.XLOOKUP(A8,'Lab-1'!A:A,'Lab-1'!G:G,"Not Completed") -> 100 | G8: =_xlfn.XLOOKUP(A8,'Lab-2'!A:A,'Lab-2'!H:H,"Not Completed") -> 98 | H8: =_xlfn.XLOOKUP(A8,'Lab-3'!A:A,'Lab-3'!H:H,"Not Completed") -> 98 | I8: =_xlfn.XLOOKUP(A8,'Lab-4'!A:A,'Lab-4'!H:H,"Not Completed") -> 92 | J8: =_xlfn.XLOOKUP(A8,'Lab-5'!A:A,'Lab-5'!H:H,"Not Completed") -> 95 | K8: =_xlfn.XLOOKUP(A8,'Lab-6'!A:A,'Lab-6'!G:G,"Not Completed") -> 100 | L8: =_xlfn.XLOOKUP(A8,'Lab-7'!A:A,'Lab-7'!H:H,"Not Completed") -> 90 | M8: =_xlfn.XLOOKUP(A8,'Lab-8'!A:A,'Lab-8'!H:H,"Not Completed") -> 95 | N8: =_xlfn.XLOOKUP(A8,'Lab-9'!A:A,'Lab-9'!H:H,"Not Completed") -> Not Completed | O8: =COUNT(F8:N8) -> 8 | P8: =COUNTIF(F8:N8,"Not Completed") -> 1
A9: AF05308380 | B9: Swathi S | C9: swathi.anitha127@gmail.com | D9: 6369082252 | E9: 96 | F9: =_xlfn.XLOOKUP(A9,'Lab-1'!A:A,'Lab-1'!G:G,"Not Completed") -> 100 | G9: =_xlfn.XLOOKUP(A9,'Lab-2'!A:A,'Lab-2'!H:H,"Not Completed") -> 98 | H9: =_xlfn.XLOOKUP(A9,'Lab-3'!A:A,'Lab-3'!H:H,"Not Completed") -> 98 | I9: =_xlfn.XLOOKUP(A9,'Lab-4'!A:A,'Lab-4'!H:H,"Not Completed") -> 96 | J9: =_xlfn.XLOOKUP(A9,'Lab-5'!A:A,'Lab-5'!H:H,"Not Completed") -> 96 | K9: =_xlfn.XLOOKUP(A9,'Lab-6'!A:A,'Lab-6'!G:G,"Not Completed") -> 100 | L9: =_xlfn.XLOOKUP(A9,'Lab-7'!A:A,'Lab-7'!H:H,"Not Completed") -> 96 | M9: =_xlfn.XLOOKUP(A9,'Lab-8'!A:A,'Lab-8'!H:H,"Not Completed") -> 96 | N9: =_xlfn.XLOOKUP(A9,'Lab-9'!A:A,'Lab-9'!H:H,"Not Completed") -> 97 | O9: =COUNT(F9:N9) -> 9 | P9: =COUNTIF(F9:N9,"Not Completed") -> 0
A10: AF05308407 | B10: Eswari M | C10: eswarim12102005@gmail.com | D10: 6384203529 | E10: 53 | F10: =_xlfn.XLOOKUP(A10,'Lab-1'!A:A,'Lab-1'!G:G,"Not Completed") -> 100 | G10: =_xlfn.XLOOKUP(A10,'Lab-2'!A:A,'Lab-2'!H:H,"Not Completed") -> Not Completed | H10: =_xlfn.XLOOKUP(A10,'Lab-3'!A:A,'Lab-3'!H:H,"Not Completed") -> Not Completed | I10: =_xlfn.XLOOKUP(A10,'Lab-4'!A:A,'Lab-4'!H:H,"Not Completed") -> Not Completed | J10: =_xlfn.XLOOKUP(A10,'Lab-5'!A:A,'Lab-5'!H:H,"Not Completed") -> Not Completed | K10: =_xlfn.XLOOKUP(A10,'Lab-6'!A:A,'Lab-6'!G:G,"Not Completed") -> Not Completed | L10: =_xlfn.XLOOKUP(A10,'Lab-7'!A:A,'Lab-7'!H:H,"Not Completed") -> Not Completed | M10: =_xlfn.XLOOKUP(A10,'Lab-8'!A:A,'Lab-8'!H:H,"Not Completed") -> Not Completed | N10: =_xlfn.XLOOKUP(A10,'Lab-9'!A:A,'Lab-9'!H:H,"Not Completed") -> Not Completed | O10: =COUNT(F10:N10) -> 1 | P10: =COUNTIF(F10:N10,"Not Completed") -> 8
A11: AF05308431 | B11: Silvan S | C11: silvannathaniel@gmail.com | D11: 7305142195 | E11: 77 | F11: =_xlfn.XLOOKUP(A11,'Lab-1'!A:A,'Lab-1'!G:G,"Not Completed") -> 100 | G11: =_xlfn.XLOOKUP(A11,'Lab-2'!A:A,'Lab-2'!H:H,"Not Completed") -> 96 | H11: =_xlfn.XLOOKUP(A11,'Lab-3'!A:A,'Lab-3'!H:H,"Not Completed") -> 95 | I11: =_xlfn.XLOOKUP(A11,'Lab-4'!A:A,'Lab-4'!H:H,"Not Completed") -> 90 | J11: =_xlfn.XLOOKUP(A11,'Lab-5'!A:A,'Lab-5'!H:H,"Not Completed") -> 95 | K11: =_xlfn.XLOOKUP(A11,'Lab-6'!A:A,'Lab-6'!G:G,"Not Completed") -> 100 | L11: =_xlfn.XLOOKUP(A11,'Lab-7'!A:A,'Lab-7'!H:H,"Not Completed") -> 90 | M11: =_xlfn.XLOOKUP(A11,'Lab-8'!A:A,'Lab-8'!H:H,"Not Completed") -> 96 | N11: =_xlfn.XLOOKUP(A11,'Lab-9'!A:A,'Lab-9'!H:H,"Not Completed") -> Not Completed | O11: =COUNT(F11:N11) -> 8 | P11: =COUNTIF(F11:N11,"Not Completed") -> 1
A12: AF05308442 | B12: Mahalakshmi AK | C12: ak.mahaarul@gmail.com | D12: 9080240033 | E12: 82 | F12: =_xlfn.XLOOKUP(A12,'Lab-1'!A:A,'Lab-1'!G:G,"Not Completed") -> 100 | G12: =_xlfn.XLOOKUP(A12,'Lab-2'!A:A,'Lab-2'!H:H,"Not Completed") -> 96 | H12: =_xlfn.XLOOKUP(A12,'Lab-3'!A:A,'Lab-3'!H:H,"Not Completed") -> 90 | I12: =_xlfn.XLOOKUP(A12,'Lab-4'!A:A,'Lab-4'!H:H,"Not Completed") -> 95 | J12: =_xlfn.XLOOKUP(A12,'Lab-5'!A:A,'Lab-5'!H:H,"Not Completed") -> 95 | K12: =_xlfn.XLOOKUP(A12,'Lab-6'!A:A,'Lab-6'!G:G,"Not Completed") -> 100 | L12: =_xlfn.XLOOKUP(A12,'Lab-7'!A:A,'Lab-7'!H:H,"Not Completed") -> 95 | M12: =_xlfn.XLOOKUP(A12,'Lab-8'!A:A,'Lab-8'!H:H,"Not Completed") -> 95 | N12: =_xlfn.XLOOKUP(A12,'Lab-9'!A:A,'Lab-9'!H:H,"Not Completed") -> 95 | O12: =COUNT(F12:N12) -> 9 | P12: =COUNTIF(F12:N12,"Not Completed") -> 0
A13: AF05308473 | B13: Nikil Raja R | C13: nikilraja31@gmail.com | D13: 7448911580 | E13: 82 | F13: =_xlfn.XLOOKUP(A13,'Lab-1'!A:A,'Lab-1'!G:G,"Not Completed") -> 100 | G13: =_xlfn.XLOOKUP(A13,'Lab-2'!A:A,'Lab-2'!H:H,"Not Completed") -> 97 | H13: =_xlfn.XLOOKUP(A13,'Lab-3'!A:A,'Lab-3'!H:H,"Not Completed") -> 95 | I13: =_xlfn.XLOOKUP(A13,'Lab-4'!A:A,'Lab-4'!H:H,"Not Completed") -> 96 | J13: =_xlfn.XLOOKUP(A13,'Lab-5'!A:A,'Lab-5'!H:H,"Not Completed") -> 95 | K13: =_xlfn.XLOOKUP(A13,'Lab-6'!A:A,'Lab-6'!G:G,"Not Completed") -> 100 | L13: =_xlfn.XLOOKUP(A13,'Lab-7'!A:A,'Lab-7'!H:H,"Not Completed") -> 95 | M13: =_xlfn.XLOOKUP(A13,'Lab-8'!A:A,'Lab-8'!H:H,"Not Completed") -> 95 | N13: =_xlfn.XLOOKUP(A13,'Lab-9'!A:A,'Lab-9'!H:H,"Not Completed") -> 95 | O13: =COUNT(F13:N13) -> 9 | P13: =COUNTIF(F13:N13,"Not Completed") -> 0
... A46: AF05313700 | B46: Amirthan M | C46: smartamirthan@gmail.com | D46: 7550375297 | E46: 14 | F46: =_xlfn.XLOOKUP(A46,'Lab-1'!A:A,'Lab-1'!G:G,"Not Completed") -> Not Completed | G46: =_xlfn.XLOOKUP(A46,'Lab-2'!A:A,'Lab-2'!H:H,"Not Completed") -> Not Completed | H46: =_xlfn.XLOOKUP(A46,'Lab-3'!A:A,'Lab-3'!H:H,"Not Completed") -> Not Completed | I46: =_xlfn.XLOOKUP(A46,'Lab-4'!A:A,'Lab-4'!H:H,"Not Completed") -> Not Completed | J46: =_xlfn.XLOOKUP(A46,'Lab-5'!A:A,'Lab-5'!H:H,"Not Completed") -> Not Completed | K46: =_xlfn.XLOOKUP(A46,'Lab-6'!A:A,'Lab-6'!G:G,"Not Completed") -> Not Completed | L46: =_xlfn.XLOOKUP(A46,'Lab-7'!A:A,'Lab-7'!H:H,"Not Completed") -> Not Completed | M46: =_xlfn.XLOOKUP(A46,'Lab-8'!A:A,'Lab-8'!H:H,"Not Completed") -> Not Completed | N46: =_xlfn.XLOOKUP(A46,'Lab-9'!A:A,'Lab-9'!H:H,"Not Completed") -> Not Completed | O46: =COUNT(F46:N46) -> 0 | P46: =COUNTIF(F46:N46,"Not Completed") -> 9
A47: AF05319991 | B47: Mohamed Irsadh A | E47: 50 | F47: =_xlfn.XLOOKUP(A47,'Lab-1'!A:A,'Lab-1'!G:G,"Not Completed") -> Not Completed | G47: =_xlfn.XLOOKUP(A47,'Lab-2'!A:A,'Lab-2'!H:H,"Not Completed") -> Not Completed | H47: =_xlfn.XLOOKUP(A47,'Lab-3'!A:A,'Lab-3'!H:H,"Not Completed") -> Not Completed | I47: =_xlfn.XLOOKUP(A47,'Lab-4'!A:A,'Lab-4'!H:H,"Not Completed") -> Not Completed | J47: =_xlfn.XLOOKUP(A47,'Lab-5'!A:A,'Lab-5'!H:H,"Not Completed") -> Not Completed | K47: =_xlfn.XLOOKUP(A47,'Lab-6'!A:A,'Lab-6'!G:G,"Not Completed") -> Not Completed | L47: =_xlfn.XLOOKUP(A47,'Lab-7'!A:A,'Lab-7'!H:H,"Not Completed") -> Not Completed | M47: =_xlfn.XLOOKUP(A47,'Lab-8'!A:A,'Lab-8'!H:H,"Not Completed") -> 95 | N47: =_xlfn.XLOOKUP(A47,'Lab-9'!A:A,'Lab-9'!H:H,"Not Completed") -> 80 | O47: =COUNT(F47:N47) -> 2 | P47: =COUNTIF(F47:N47,"Not Completed") -> 7

Sheet MCQ

Sheet Lab-9
A1: User ID | B1: Center Code | C1: Batch Code | D1: First Name/Surname | E1: Email | F1: Status | G1: Total Marks | H1: Marks | I1: Last modified (submission) | J1: File submission | K1: Online text
A2: af05313343 | B2: TNDBS | C2: ANP-D7435 | D2: Vikram G | E2: vikramprofessional11@gmail.com | F2: Graded | G2: 100 | H2: 80 | I2: Tuesday, 25 August 2026, 5:01 PM | J2: photo_2026-08-25_16-59-46.jpg
A3: af05308512 | B3: TNDBS | C3: ANP-D7435 | D3: Sandra Sebastian | E3: sandrasebastian000@gmail.com | F3: Graded | G3: 100 | H3: 96 | I3: Tuesday, 25 August 2026, 5:23 PM | J3: task9.pdf
A4: af05308380 | B4: TNDBS | C4: ANP-D7435 | D4: Swathi S | E4: swathi.anitha127@gmail.com | F4: Graded | G4: 100 | H4: 97 | I4: Tuesday, 25 August 2026, 5:28 PM | J4: DAX_Date_Time_Task_Index_Report.pdf | K4: Student Name:
A5: af05308489 | B5: TNDBS | C5: ANP-D7435 | D5: Sandhiya M | E5: msandhiya124@gmail.com | F5: Graded | G5: 100 | H5: 95 | I5: Tuesday, 25 August 2026, 5:28 PM | J5: Lab 9.pdf
A6: af05319991 | B6: TNDBS | C6: ANP-D7435 | D6: Mohamed Irsadh A | E6: mohamedirsadh.digi@gmail.com | F6: Graded | G6: 100 | H6: 80 | I6: Tuesday, 25 August 2026, 5:48 PM | J6: Dax Date Functions.png
A7: af05308992 | B7: TNDBS | C7: ANP-D7435 | D7: Santhosh Raj N | E7: santhoshjn11@gmail.com | F7: Graded | G7: 100 | H7: 80 | I7: Tuesday, 25 August 2026, 9:25 PM | J7: Screenshot 2026-08-25 212101.png
A8: af05309824 | B8: TNDBS | C8: ANP-D7435 | D8: Hariharan S | E8: hariharanst0203@gmail.com | F8: Graded | G8: 100 | H8: 85 | I8: Tuesday, 25 August 2026, 10:22 PM | J8: Lab-9 Date Functions.pdf
A9: af05311479 | B9: TNDBS | C9: ANP-D7435 | D9: Pavithra S | E9: pavithrasekar1692003@gmail.com | F9: Graded | G9: 100 | H9: 90 | I9: Tuesday, 25 August 2026, 10:28 PM | J9: LMS DAX_removed.pdf
A10: af05309275 | B10: TNDBS | C10: ANP-D7435 | D10: Annett George | E10: georgeannette24@gmail.com | F10: Graded | G10: 100 | H10: 90 | I10: Wednesday, 26 August 2026, 10:24 AM | J10: Screenshot 2026-08-26 100746.png
A11: af05308375 | B11: TNDBS | C11: ANP-D7435 | D11: Joe william A | E11: joewilliam147@gmail.com | F11: Graded | G11: 100 | H11: 90 | I11: Wednesday, 26 August 2026, 10:35 AM | J11: TASK_9.pdf
A12: af05308156 | B12: TNDBS | C12: ANP-D7435 | D12: Gowtham S | E12: gowthams2k20@gmail.com | F12: Graded | G12: 100 | H12: 90 | I12: Wednesday, 26 August 2026, 10:42 AM | J12: TASK_9.pdf
A13: af05308357 | B13: TNDBS | C13: ANP-D7435 | D13: Syed Sarferaz Sajid A | E13: sarferazsajid77@gmail.com | F13: Graded | G13: 100 | H13: 90 | I13: Wednesday, 26 August 2026, 11:24 AM | J13: TASK_9.pdf
A14: af05308381 | B14: TNDBS | C14: ANP-D7435 | D14: Aarthi R | E14: aarthirajaguru63@gmail.com | F14: Graded | G14: 100 | H14: 95 | I14: Wednesday, 26 August 2026, 11:32 AM | J14: AARTHI_R_POWERBI(DAX)_3.pdf
A15: af05309754 | B15: TNDBS | C15: ANP-D7435 | D15: Harish B | E15: harishbalaji147@gmail.com | F15: Graded | G15: 100 | H15: 95 | I15: Wednesday, 26 August 2026, 11:58 AM | J15: Harish-Lab-9.pdf | K15: DAX Creating the new table and
A16: af05308373 | B16: TNDBS | C16: ANP-D7435 | D16: Sivaranjani T | E16: Sivaranjanithillai2010@gmail.com | F16: Graded | G16: 100 | H16: 95 | I16: Wednesday, 26 August 2026, 12:13 PM | J16: POWER QUERY 3.pdf
A17: af05308382 | B17: TNDBS | C17: ANP-D7435 | D17: Harini M | E17: mharini0701@gmail.com | F17: Graded | G17: 100 | H17: 95 | I17: Wednesday, 26 August 2026, 1:56 PM | J17: Harini_Lab_Task09.pdf
A18: af05309665 | B18: TNDBS | C18: ANP-D7435 | D18: Jagadeeswary T | E18: jagadeeswary2006@gmail.com | F18: Graded | G18: 100 | H18: 95 | I18: Wednesday, 26 August 2026, 1:57 PM | J18: Lab9.pdf
A19: af05309827 | B19: TNDBS | C19: ANP-D7435 | D19: Thamarai Selvan N | E19: thamaraiselvan358@gmail.com | F19: Graded | G19: 100 | H19: 95 | I19: Wednesday, 26 August 2026, 1:58 PM | J19: LAB-9.pdf
A20: af05308359 | B20: TNDBS | C20: ANP-D7435 | D20: Sasidharan A | E20: sasidh9198@gmail.com | F20: Graded | G20: 100 | H20: 95 | I20: Wednesday, 26 August 2026, 2:18 PM | J20: Lab_9 Dax.pdf
A21: af05313450 | B21: TNDBS | C21: ANP-D7435 | D21: Mohamed Shahir Hussain G | E21: shahir.157igms@gmail.com | F21: Graded | G21: 100 | H21: 90 | I21: Wednesday, 26 August 2026, 2:48 PM | J21: TASK_9.docx
A22: af05308442 | B22: TNDBS | C22: ANP-D7435 | D22: Mahalakshmi AK | E22: ak.mahaarul@gmail.com | F22: Graded | G22: 100 | H22: 95 | I22: Wednesday, 26 August 2026, 2:59 PM | J22: MAHALAKSHMI A K_LAB9.pdf
A23: af05308473 | B23: TNDBS | C23: ANP-D7435 | D23: Nikil Raja R | E23: nikilraja31@gmail.com | F23: Graded | G23: 100 | H23: 95 | I23: Wednesday, 26 August 2026, 3:02 PM | J23: NIKIL RAJA R LAB-9.pdf
A24: af05308353 | B24: TNDBS | C24: ANP-D7435 | D24: Varshini A S | E24: varshinivela2309@gmail.com | F24: Graded | G24: 100 | H24: 95 | I24: Wednesday, 26 August 2026, 3:02 PM | J24: power bi task2.pdf
A25: af05308383 | B25: TNDBS | C25: ANP-D7435 | D25: Yuvaraj M | E25: yuvayuvaraj331@gmail.com | F25: Graded | G25: 100 | H25: 95 | I25: Wednesday, 26 August 2026, 11:55 PM | J25: DAX.pdf
A26: af05308766 | B26: TNDBS | C26: ANP-D7435 | D26: Nithish G | E26: gtnithish2003@gmail.com | F26: Graded | G26: 100 | H26: 95 | I26: Thursday, 27 August 2026, 12:48 PM | J26: Lab9task.pdf | K26: I have Successfully Completed T
A27: af05309846 | B27: TNDBS | C27: ANP-D7435 | D27: Vansh Vijeynath B | E27: vanshvijeynath27@gmail.com | F27: Graded | G27: 100 | H27: 90 | I27: Thursday, 27 August 2026, 3:53 PM | J27: Vansh Vijeynath LAB 9.pdf
A28: af05310365 | B28: TNDBS | C28: ANP-D7435 | D28: Kishori J | E28: kishori200510@gmail.com | F28: Graded | G28: 100 | H28: 93 | I28: Thursday, 27 August 2026, 4:30 PM | J28: DAX.pdf
A29: af05313301 | B29: TNDBS | C29: ANP-D7435 | D29: Saravana Prabu V | E29: saravanaprabuv5@gmail.com | F29: Graded | G29: 100 | H29: 93 | I29: Friday, 28 August 2026, 10:29 AM | J29: saravana dax.pdf
A30: af05308793 | B30: TNDBS | C30: ANP-D7435 | D30: Surya Narayanan Rameshbabu | E30: workpp2025may@gmail.com | F30: Graded | G30: 100 | H30: 90 | I30: Friday, 28 August 2026, 11:33 PM | J30: Surya Narayanan R LAB 9.pbix

Sheet Lab-8
A1: User ID | B1: Center Code | C1: Batch Code | D1: First Name/Surname | E1: Email | F1: Status | G1: Total Marks | H1: Marks | I1: Last modified (submission) | J1: File submission | K1: Online text
A2: af05308992 | B2: TNDBS | C2: ANP-D7435 | D2: Santhosh Raj N | E2: santhoshjn11@gmail.com | F2: Graded | G2: 100 | H2: 95 | I2: Thursday, 20 August 2026, 4:49 PM | J2: Group by region.pdf
A3: af05308376 | B3: TNDBS | C3: ANP-D7435 | D3: Satheesh Kumar G | E3: satheeshkumar14796@gmail.com | F3: Graded | G3: 100 | H3: 95 | I3: Thursday, 20 August 2026, 4:52 PM | J3: Satheesh_Kumar_G-Lab-8.pdf | K3: Power BI - Power Query - Group
A4: af05308119 | B4: TNDBS | C4: ANP-D7435 | D4: Keerthikraj J | E4: jpkeerthik30@gmail.com | F4: Graded | G4: 100 | H4: 95 | I4: Thursday, 20 August 2026, 4:54 PM | J4: Advance Groupby.pdf | K4: The task groups
A5: af05308119 | B5: TNDBS | C5: ANP-D7435 | D5: Keerthikraj J | E5: jpkeerthik30@gmail.com | F5: Graded | G5: 100 | H5: 95 | I5: Thursday, 20 August 2026, 4:54 PM | J5: Advance Groupby.pdf | K5: The task groups
A6: af05308375 | B6: TNDBS | C6: ANP-D7435 | D6: Joe william A | E6: joewilliam147@gmail.com | F6: Graded | G6: 100 | H6: 95 | I6: Thursday, 20 August 2026, 4:57 PM | J6: TASK_8.pdf
A7: af05308512 | B7: TNDBS | C7: ANP-D7435 | D7: Sandra Sebastian | E7: sandrasebastian000@gmail.com | F7: Graded | G7: 100 | H7: 95 | I7: Thursday, 20 August 2026, 4:58 PM | J7: task8.pdf
A8: af05310365 | B8: TNDBS | C8: ANP-D7435 | D8: Kishori J | E8: kishori200510@gmail.com | F8: Graded | G8: 100 | H8: 95 | I8: Thursday, 20 August 2026, 4:58 PM | J8: LAB7.pdf
A9: af05308156 | B9: TNDBS | C9: ANP-D7435 | D9: Gowtham S | E9: gowthams2k20@gmail.com | F9: Graded | G9: 100 | H9: 95 | I9: Thursday, 20 August 2026, 5:00 PM | J9: task_8.pdf
A10: af05308353 | B10: TNDBS | C10: ANP-D7435 | D10: Varshini A S | E10: varshinivela2309@gmail.com | F10: Graded | G10: 100 | H10: 95 | I10: Thursday, 20 August 2026, 5:00 PM | J10: varshini lab task 8.pdf
A11: af05308381 | B11: TNDBS | C11: ANP-D7435 | D11: Aarthi R | E11: aarthirajaguru63@gmail.com | F11: Graded | G11: 100 | H11: 95 | I11: Thursday, 20 August 2026, 5:00 PM | J11: AARTHI_R_POWERQUERY_2.pdf
A12: af05308373 | B12: TNDBS | C12: ANP-D7435 | D12: Sivaranjani T | E12: Sivaranjanithillai2010@gmail.com | F12: Graded | G12: 100 | H12: 95 | I12: Thursday, 20 August 2026, 5:02 PM | J12: sivaranjani T Lab 8.pdf
A13: af05309846 | B13: TNDBS | C13: ANP-D7435 | D13: Vansh Vijeynath B | E13: vanshvijeynath27@gmail.com | F13: Graded | G13: 100 | H13: 95 | I13: Thursday, 20 August 2026, 5:03 PM | J13: Vansh Vijeynath B LAB 8.pdf
A14: af05309275 | B14: TNDBS | C14: ANP-D7435 | D14: Annett George | E14: georgeannette24@gmail.com | F14: Graded | G14: 100 | H14: 95 | I14: Thursday, 20 August 2026, 5:04 PM | J14: Screenshot 2026-08-20 170017.png
A15: af05319991 | B15: TNDBS | C15: ANP-D7435 | D15: Mohamed Irsadh A | E15: mohamedirsadh.digi@gmail.com | F15: Graded | G15: 100 | H15: 95 | I15: Thursday, 20 August 2026, 5:11 PM | J15: Advanced Group_By.png
A16: af05313301 | B16: TNDBS | C16: ANP-D7435 | D16: Saravana Prabu V | E16: saravanaprabuv5@gmail.com | F16: Graded | G16: 100 | H16: 95 | I16: Thursday, 20 August 2026, 5:19 PM | J16: lab 8 answer.pdf
A17: af05308489 | B17: TNDBS | C17: ANP-D7435 | D17: Sandhiya M | E17: msandhiya124@gmail.com | F17: Graded | G17: 100 | H17: 95 | I17: Thursday, 20 August 2026, 5:29 PM | J17: Lab 8.pdf
... A26: af05308442 | B26: TNDBS | C26: ANP-D7435 | D26: Mahalakshmi AK | E26: ak.mahaarul@gmail.com | F26: Graded | G26: 100 | H26: 95 | I26: Thursday, 20 August 2026, 11:25 PM | J26: Mahalakshmi A K Lab-8.pdf
A27: af05308766 | B27: TNDBS | C27: ANP-D7435 | D27: Nithish G | E27: gtnithish2003@gmail.com | F27: Graded | G27: 100 | H27: 95 | I27: Friday, 21 August 2026, 10:08 AM | J27: GroupBY.pdf | K27: I successfully Completed this L
A28: af05309827 | B28: TNDBS | C28: ANP-D7435 | D28: Thamarai Selvan N | E28: thamaraiselvan358@gmail.com | F28: Graded | G28: 100 | H28: 95 | I28: Friday, 21 August 2026, 1:05 PM | J28: LAB-8.pdf
A29: af05310227 | B29: TNDBS | C29: ANP-D7435 | D29: Sanjai P | E29: sanjaip6010@gmail.com | F29: Graded | G29: 100 | H29: 95 | I29: Friday, 21 August 2026, 1:53 PM | J29: Lab 8.pdf
A30: af05308357 | B30: TNDBS | C30: ANP-D7435 | D30: Syed Sarferaz Sajid A | E30: sarferazsajid77@gmail.com | F30: Graded | G30: 100 | H30: 95 | I30: Friday, 21 August 2026, 3:19 PM | J30: Task 8.pdf
A31: af05308382 | B31: TNDBS | C31: ANP-D7435 | D31: Harini M | E31: mharini0701@gmail.com | F31: Graded | G31: 100 | H31: 95 | I31: Friday, 21 August 2026, 3:36 PM | J31: Harini_Lab_Task08.pdf
A32: af05309754 | B32: TNDBS | C32: ANP-D7435 | D32: Harish B | E32: harishbalaji147@gmail.com | F32: Graded | G32: 100 | H32: 95 | I32: Sunday, 23 August 2026, 2:58 PM | J32: Harish-Lab-8.pdf | K32: GROUPBY usage
A33: af05308793 | B33: TNDBS | C33: ANP-D7435 | D33: Surya Narayanan Rameshbabu | E33: workpp2025may@gmail.com | F33: Graded | G33: 100 | H33: 95 | I33: Tuesday, 25 August 2026, 12:02 AM | J33: Surya Narayanan R LAB 8.pbix
A34: af05309824 | B34: TNDBS | C34: ANP-D7435 | D34: Hariharan S | E34: hariharanst0203@gmail.com | F34: Graded | G34: 100 | H34: 95 | I34: Tuesday, 25 August 2026, 3:00 PM | J34: Lab-8 Advanced Group by .pdf
A35: af05308374 | B35: TNDBS | C35: ANP-D7435 | D35: Lakshmikanthan G | E35: lakshug999@gmail.com | F35: Graded | G35: 100 | H35: 95 | I35: Wednesday, 26 August 2026, 1:39 PM | J35: Screenshot 2026-08-26 133732.png
A36: af05308431 | B36: TNDBS | C36: ANP-D7435 | D36: Silvan S | E36: silvannathaniel@gmail.com | F36: Graded | G36: 100 | H36: 96 | I36: Wednesday, 26 August 2026, 2:46 PM | J36: Task-8 Power query (AFO5308431).pdf

Sheet Lab-7
A1: User ID | B1: Center Code | C1: Batch Code | D1: First Name/Surname | E1: Email | F1: Status | G1: Total Marks | H1: Marks | I1: Last modified (submission) | J1: File submission | K1: Online text
A2: af05308373 | B2: TNDBS | C2: ANP-D7435 | D2: Sivaranjani T | E2: Sivaranjanithillai2010@gmail.com | F2: Graded | G2: 100 | H2: 95 | I2: Tuesday, 18 August 2026, 5:08 PM | J2: Sivaranjani T lab7.pdf
A3: af05308380 | B3: TNDBS | C3: ANP-D7435 | D3: Swathi S | E3: swathi.anitha127@gmail.com | F3: Graded | G3: 100 | H3: 96 | I3: Tuesday, 18 August 2026, 5:15 PM | J3: PowerBI_Merge_Tables_Report.pdf | K3: <
A4: af05308512 | B4: TNDBS | C4: ANP-D7435 | D4: Sandra Sebastian | E4: sandrasebastian000@gmail.com | F4: Graded | G4: 100 | H4: 95 | I4: Tuesday, 18 August 2026, 5:16 PM | J4: task7.pdf
A5: af05308992 | B5: TNDBS | C5: ANP-D7435 | D5: Santhosh Raj N | E5: santhoshjn11@gmail.com | F5: Graded | G5: 100 | H5: 80 | I5: Tuesday, 18 August 2026, 6:29 PM | J5: Screenshot 2026-08-18 182538.png
A6: af05308442 | B6: TNDBS | C6: ANP-D7435 | D6: Mahalakshmi AK | E6: ak.mahaarul@gmail.com | F6: Graded | G6: 100 | H6: 95 | I6: Tuesday, 18 August 2026, 7:09 PM | J6: MAHALAKSHMI A K_LAB7.pdf
A7: af05308473 | B7: TNDBS | C7: ANP-D7435 | D7: Nikil Raja R | E7: nikilraja31@gmail.com | F7: Graded | G7: 100 | H7: 95 | I7: Tuesday, 18 August 2026, 7:13 PM | J7: NIKIL RAJA R LAB-7.pdf
A8: af05308793 | B8: TNDBS | C8: ANP-D7435 | D8: Surya Narayanan Rameshbabu | E8: workpp2025may@gmail.com | F8: Graded | G8: 100 | H8: 90 | I8: Tuesday, 18 August 2026, 7:25 PM | J8: Surya Narayanan R LAB 7.pbix
A9: af05308489 | B9: TNDBS | C9: ANP-D7435 | D9: Sandhiya M | E9: msandhiya124@gmail.com | F9: Graded | G9: 100 | H9: 95 | I9: Tuesday, 18 August 2026, 7:57 PM | J9: Lab 7.pdf
A10: af05309665 | B10: TNDBS | C10: ANP-D7435 | D10: Jagadeeswary T | E10: jagadeeswary2006@gmail.com | F10: Graded | G10: 100 | H10: 95 | I10: Tuesday, 18 August 2026, 8:54 PM | J10: Lab2.pdf
A11: af05308381 | B11: TNDBS | C11: ANP-D7435 | D11: Aarthi R | E11: aarthirajaguru63@gmail.com | F11: Graded | G11: 100 | H11: 95 | I11: Tuesday, 18 August 2026, 9:28 PM | J11: AARTHI_R_EXCEL7.pdf
A12: af05308376 | B12: TNDBS | C12: ANP-D7435 | D12: Satheesh Kumar G | E12: satheeshkumar14796@gmail.com | F12: Graded | G12: 100 | H12: 90 | I12: Tuesday, 18 August 2026, 9:44 PM | J12: Satheesh_Kumar_G-Lab-7.pdf | K12: Merge Tables in Power BI
A13: af05308375 | B13: TNDBS | C13: ANP-D7435 | D13: Joe william A | E13: joewilliam147@gmail.com | F13: Graded | G13: 100 | H13: 95 | I13: Tuesday, 18 August 2026, 10:00 PM | J13: TASK_7.pdf
A14: af05310365 | B14: TNDBS | C14: ANP-D7435 | D14: Kishori J | E14: kishori200510@gmail.com | F14: Graded | G14: 100 | H14: 96 | I14: Tuesday, 18 August 2026, 10:02 PM | J14: LAB7.pdf | K14: inner join
A15: af05311479 | B15: TNDBS | C15: ANP-D7435 | D15: Pavithra S | E15: pavithrasekar1692003@gmail.com | F15: Graded | G15: 100 | H15: 96 | I15: Tuesday, 18 August 2026, 10:10 PM | J15: LMS 7th Task.pdf
A16: af05308431 | B16: TNDBS | C16: ANP-D7435 | D16: Silvan S | E16: silvannathaniel@gmail.com | F16: Graded | G16: 100 | H16: 90 | I16: Tuesday, 18 August 2026, 11:38 PM | J16: Task-7 (AFO5308431).pdf
A17: af05313301 | B17: TNDBS | C17: ANP-D7435 | D17: Saravana Prabu V | E17: saravanaprabuv5@gmail.com | F17: Graded | G17: 100 | H17: 90 | I17: Tuesday, 18 August 2026, 11:55 PM | J17: task7.pdf
A18: af05308382 | B18: TNDBS | C18: ANP-D7435 | D18: Harini M | E18: mharini0701@gmail.com | F18: Graded | G18: 100 | H18: 97 | I18: Wednesday, 19 August 2026, 12:13 AM | J18: Harini_Lab_Task07.pdf
A19: af05308357 | B19: TNDBS | C19: ANP-D7435 | D19: Syed Sarferaz Sajid A | E19: sarferazsajid77@gmail.com | F19: Graded | G19: 100 | H19: 94 | I19: Wednesday, 19 August 2026, 9:08 AM | J19: TASK_7 Syed.docx
A20: af05308156 | B20: TNDBS | C20: ANP-D7435 | D20: Gowtham S | E20: gowthams2k20@gmail.com | F20: Graded | G20: 100 | H20: 95 | I20: Wednesday, 19 August 2026, 11:04 AM | J20: TASK_7.pdf
A21: af05308359 | B21: TNDBS | C21: ANP-D7435 | D21: Sasidharan A | E21: sasidh9198@gmail.com | F21: Graded | G21: 100 | H21: 95 | I21: Wednesday, 19 August 2026, 2:04 PM | J21: LAB_7.pdf
A22: af05308383 | B22: TNDBS | C22: ANP-D7435 | D22: Yuvaraj M | E22: yuvayuvaraj331@gmail.com | F22: Graded | G22: 100 | H22: 95 | I22: Wednesday, 19 August 2026, 2:13 PM | J22: Merge Table from Powerbi.pdf
A23: af05313450 | B23: TNDBS | C23: ANP-D7435 | D23: Mohamed Shahir Hussain G | E23: shahir.157igms@gmail.com | F23: Graded | G23: 100 | H23: 94 | I23: Wednesday, 19 August 2026, 2:59 PM | J23: TASK_7.docx
A24: af05309827 | B24: TNDBS | C24: ANP-D7435 | D24: Thamarai Selvan N | E24: thamaraiselvan358@gmail.com | F24: Graded | G24: 100 | H24: 95 | I24: Wednesday, 19 August 2026, 10:21 PM | J24: LAB-7 (1).pdf
A25: af05309846 | B25: TNDBS | C25: ANP-D7435 | D25: Vansh Vijeynath B | E25: vanshvijeynath27@gmail.com | F25: Graded | G25: 100 | H25: 95 | I25: Thursday, 20 August 2026, 12:38 PM | J25: Vansh Vijeynath B LAB 7.pdf
A26: af05309275 | B26: TNDBS | C26: ANP-D7435 | D26: Annett George | E26: georgeannette24@gmail.com | F26: Graded | G26: 100 | H26: 90 | I26: Thursday, 20 August 2026, 2:55 PM | J26: Screenshot 2026-08-20 145314.png
A27: af05308119 | B27: TNDBS | C27: ANP-D7435 | D27: Keerthikraj J | E27: jpkeerthik30@gmail.com | F27: Graded | G27: 100 | H27: 90 | I27: Thursday, 20 August 2026, 4:11 PM | J27: Merge Table from Powerbi.pdf | K27: It contains colu
A28: af05308766 | B28: TNDBS | C28: ANP-D7435 | D28: Nithish G | E28: gtnithish2003@gmail.com | F28: Graded | G28: 100 | H28: 95 | I28: Thursday, 20 August 2026, 8:07 PM | J28: Task 7.pdf | K28: i successfully completed This L
A29: af05309824 | B29: TNDBS | C29: ANP-D7435 | D29: Hariharan S | E29: hariharanst0203@gmail.com | F29: Graded | G29: 100 | H29: 96 | I29: Thursday, 20 August 2026, 9:55 PM | J29: Merge in Power query .pdf
A30: af05308353 | B30: TNDBS | C30: ANP-D7435 | D30: Varshini A S | E30: varshinivela2309@gmail.com | F30: Graded | G30: 100 | H30: 96 | I30: Friday, 21 August 2026, 2:46 PM | J30: Varshini lab task 7.pdf
A31: af05309754 | B31: TNDBS | C31: ANP-D7435 | D31: Harish B | E31: harishbalaji147@gmail.com | F31: Graded | G31: 100 | H31: 90 | I31: Sunday, 23 August 2026, 11:57 AM | J31: Harish-Lab-7.pdf
A32: af05308374 | B32: TNDBS | C32: ANP-D7435 | D32: Lakshmikanthan G | E32: lakshug999@gmail.com | F32: Graded | G32: 100 | H32: 80 | I32: Wednesday, 26 August 2026, 12:59 PM | J32: Screenshot 2026-08-26 125254.png

Sheet Lab-6
A1: User ID | B1: Center Code | C1: Batch Code | D1: First Name/Surname | E1: Email | F1: Status | G1: Total Marks | H1: Marks | I1: Last modified (submission) | J1: File submission | K1: Online text
A2: af05308512 | B2: TNDBS | C2: ANP-D7435 | D2: Sandra Sebastian | E2: sandrasebastian000@gmail.com | F2: Graded | G2: 100 | I2: Monday, 17 August 2026, 5:16 PM | J2: task6.pdf
A3: af05308992 | B3: TNDBS | C3: ANP-D7435 | D3: Santhosh Raj N | E3: santhoshjn11@gmail.com | F3: Graded | G3: 100 | I3: Monday, 17 August 2026, 6:20 PM | J3: power bi 1.pdf
A4: af05309275 | B4: TNDBS | C4: ANP-D7435 | D4: Annett George | E4: georgeannette24@gmail.com | F4: Graded | G4: 100 | I4: Monday, 17 August 2026, 7:49 PM | J4: Screenshot 2026-08-17 194624.pdf
A5: af05309665 | B5: TNDBS | C5: ANP-D7435 | D5: Jagadeeswary T | E5: jagadeeswary2006@gmail.com | F5: Graded | G5: 100 | I5: Monday, 17 August 2026, 8:18 PM | J5: 6Lab.pdf
A6: af05308380 | B6: TNDBS | C6: ANP-D7435 | D6: Swathi S | E6: swathi.anitha127@gmail.com | F6: Graded | G6: 100 | I6: Monday, 17 August 2026, 9:13 PM | J6: PowerBI_Power_Query_Editor_Task.pdf | K6: <
A7: af05308373 | B7: TNDBS | C7: ANP-D7435 | D7: Sivaranjani T | E7: Sivaranjanithillai2010@gmail.com | F7: Graded | G7: 100 | I7: Monday, 17 August 2026, 9:45 PM | J7: sivaranjani T Lab 6.pdf
A8: af05308381 | B8: TNDBS | C8: ANP-D7435 | D8: Aarthi R | E8: aarthirajaguru63@gmail.com | F8: Graded | G8: 100 | I8: Monday, 17 August 2026, 9:51 PM | J8: AARTHI_R_EXCEL6.pdf
A9: af05308375 | B9: TNDBS | C9: ANP-D7435 | D9: Joe william A | E9: joewilliam147@gmail.com | F9: Graded | G9: 100 | I9: Tuesday, 18 August 2026, 9:37 AM | J9: TASK_6.pdf
A10: af05308357 | B10: TNDBS | C10: ANP-D7435 | D10: Syed Sarferaz Sajid A | E10: sarferazsajid77@gmail.com | F10: Graded | G10: 100 | I10: Tuesday, 18 August 2026, 9:53 AM | J10: Task 6 Power Query.pdf
A11: af05308156 | B11: TNDBS | C11: ANP-D7435 | D11: Gowtham S | E11: gowthams2k20@gmail.com | F11: Graded | G11: 100 | I11: Tuesday, 18 August 2026, 11:41 AM | J11: POWER QUERY.pdf
A12: af05310365 | B12: TNDBS | C12: ANP-D7435 | D12: Kishori J | E12: kishori200510@gmail.com | F12: Graded | G12: 100 | I12: Tuesday, 18 August 2026, 11:52 AM | J12: POWER_BI.pdf
A13: af05308382 | B13: TNDBS | C13: ANP-D7435 | D13: Harini M | E13: mharini0701@gmail.com | F13: Graded | G13: 100 | I13: Tuesday, 18 August 2026, 12:17 PM | J13: Harini_Lab_Task06.pdf
A14: af05309827 | B14: TNDBS | C14: ANP-D7435 | D14: Thamarai Selvan N | E14: thamaraiselvan358@gmail.com | F14: Graded | G14: 100 | I14: Tuesday, 18 August 2026, 1:18 PM | J14: LAB-6.pdf
A15: af05308359 | B15: TNDBS | C15: ANP-D7435 | D15: Sasidharan A | E15: sasidh9198@gmail.com | F15: Graded | G15: 100 | I15: Tuesday, 18 August 2026, 1:51 PM | J15: POWER QUERY_Lab.pdf
A16: af05308353 | B16: TNDBS | C16: ANP-D7435 | D16: Varshini A S | E16: varshinivela2309@gmail.com | F16: Graded | G16: 100 | I16: Tuesday, 18 August 2026, 2:24 PM | J16: Varsh lab task -6.pdf
A17: af05311479 | B17: TNDBS | C17: ANP-D7435 | D17: Pavithra S | E17: pavithrasekar1692003@gmail.com | F17: Graded | G17: 100 | I17: Tuesday, 18 August 2026, 3:01 PM | J17: LMS 6th Task.pdf
A18: af05309824 | B18: TNDBS | C18: ANP-D7435 | D18: Hariharan S | E18: hariharanst0203@gmail.com | F18: Graded | G18: 100 | I18: Tuesday, 18 August 2026, 3:11 PM | J18: Power Query Editor .pdf
... A25: af05308473 | B25: TNDBS | C25: ANP-D7435 | D25: Nikil Raja R | E25: nikilraja31@gmail.com | F25: Graded | G25: 100 | I25: Tuesday, 18 August 2026, 7:11 PM | J25: NIKIL RAJA LAB-6.pdf
A26: af05308376 | B26: TNDBS | C26: ANP-D7435 | D26: Satheesh Kumar G | E26: satheeshkumar14796@gmail.com | F26: Graded | G26: 100 | I26: Tuesday, 18 August 2026, 9:29 PM | J26: Satheesh_Kumar_G-Lab-6.pdf | K26: Power Query in Power BI
A27: af05308431 | B27: TNDBS | C27: ANP-D7435 | D27: Silvan S | E27: silvannathaniel@gmail.com | F27: Graded | G27: 100 | I27: Tuesday, 18 August 2026, 10:10 PM | J27: Task-6 (AFO5308431).pdf
A28: af05313301 | B28: TNDBS | C28: ANP-D7435 | D28: Saravana Prabu V | E28: saravanaprabuv5@gmail.com | F28: Graded | G28: 100 | I28: Tuesday, 18 August 2026, 11:53 PM | J28: task 6.pdf
A29: af05308383 | B29: TNDBS | C29: ANP-D7435 | D29: Yuvaraj M | E29: yuvayuvaraj331@gmail.com | F29: Graded | G29: 100 | I29: Wednesday, 19 August 2026, 1:56 PM | J29: powerbi power query editor.pdf
A30: af05309846 | B30: TNDBS | C30: ANP-D7435 | D30: Vansh Vijeynath B | E30: vanshvijeynath27@gmail.com | F30: Graded | G30: 100 | I30: Thursday, 20 August 2026, 12:25 PM | J30: Vansh Vijeynath B LAB 6.pdf
A31: af05310678 | B31: TNDBS | C31: ANP-D7435 | D31: Afrin M | E31: afu170798@gmail.com | F31: Graded | G31: 100 | I31: Thursday, 20 August 2026, 1:01 PM | J31: lab 6.pdf
A32: af05308766 | B32: TNDBS | C32: ANP-D7435 | D32: Nithish G | E32: gtnithish2003@gmail.com | F32: Graded | G32: 100 | I32: Thursday, 20 August 2026, 7:48 PM | J32: PowerQuery.pdf | K32: i Have Successfully Completed t
A33: af05309754 | B33: TNDBS | C33: ANP-D7435 | D33: Harish B | E33: harishbalaji147@gmail.com | F33: Graded | G33: 100 | I33: Sunday, 23 August 2026, 10:59 AM | J33: Harish-Lab-6.pdf

Sheet Lab-5
A1: User ID | B1: Center Code | C1: Batch Code | D1: First Name/Surname | E1: Email | F1: Status | G1: Total Marks | H1: Marks | I1: Last modified (submission) | J1: File submission | K1: Online text
A2: af05308512 | B2: TNDBS | C2: ANP-D7435 | D2: Sandra Sebastian | E2: sandrasebastian000@gmail.com | F2: Graded | G2: 100 | H2: 95 | I2: Tuesday, 11 August 2026, 4:31 PM | J2: task5.pdf
A3: af05308119 | B3: TNDBS | C3: ANP-D7435 | D3: Keerthikraj J | E3: jpkeerthik30@gmail.com | F3: Graded | G3: 100 | H3: 95 | I3: Tuesday, 11 August 2026, 4:47 PM | J3: Index Match.pdf | K3: Task Description :
A4: af05309665 | B4: TNDBS | C4: ANP-D7435 | D4: Jagadeeswary T | E4: jagadeeswary2006@gmail.com | F4: Graded | G4: 100 | H4: 95 | I4: Tuesday, 11 August 2026, 4:57 PM | J4: jaga_lab5.pdf
A5: af05310365 | B5: TNDBS | C5: ANP-D7435 | D5: Kishori J | E5: kishori200510@gmail.com | F5: Graded | G5: 100 | H5: 95 | I5: Tuesday, 11 August 2026, 6:11 PM | J5: LAB5.pdf
A6: af05311479 | B6: TNDBS | C6: ANP-D7435 | D6: Pavithra S | E6: pavithrasekar1692003@gmail.com | F6: Graded | G6: 100 | H6: 95 | I6: Tuesday, 11 August 2026, 6:41 PM | J6: LMS 5 index match.pdf
A7: af05308375 | B7: TNDBS | C7: ANP-D7435 | D7: Joe william A | E7: joewilliam147@gmail.com | F7: Graded | G7: 100 | H7: 95 | I7: Tuesday, 11 August 2026, 7:43 PM | J7: TASK_5.pdf
A8: af05309846 | B8: TNDBS | C8: ANP-D7435 | D8: Vansh Vijeynath B | E8: vanshvijeynath27@gmail.com | F8: Graded | G8: 100 | H8: 95 | I8: Tuesday, 11 August 2026, 8:06 PM | J8: Vansh Vijeynath LAB 5.pdf
A9: af05308489 | B9: TNDBS | C9: ANP-D7435 | D9: Sandhiya M | E9: msandhiya124@gmail.com | F9: Graded | G9: 100 | H9: 95 | I9: Tuesday, 11 August 2026, 8:16 PM | J9: LAB 5.pdf | K9: I Have Completed my Lab 5 and S
A10: af05308376 | B10: TNDBS | C10: ANP-D7435 | D10: Satheesh Kumar G | E10: satheeshkumar14796@gmail.com | F10: Graded | G10: 100 | H10: 95 | I10: Tuesday, 11 August 2026, 8:19 PM | J10: Satheesh_Kumar_G-Lab-5.pdf | K10: Index & Match
A11: af05308992 | B11: TNDBS | C11: ANP-D7435 | D11: Santhosh Raj N | E11: santhoshjn11@gmail.com | F11: Graded | G11: 100 | H11: 90 | I11: Tuesday, 11 August 2026, 9:31 PM | J11: task INDEX1.pdf
A12: af05308353 | B12: TNDBS | C12: ANP-D7435 | D12: Varshini A S | E12: varshinivela2309@gmail.com | F12: Graded | G12: 100 | H12: 95 | I12: Tuesday, 11 August 2026, 9:59 PM | J12: Varshini lab task 5.pdf
A13: af05308380 | B13: TNDBS | C13: ANP-D7435 | D13: Swathi S | E13: swathi.anitha127@gmail.com | F13: Graded | G13: 100 | H13: 96 | I13: Tuesday, 11 August 2026, 10:21 PM | J13: TASK 5_INDEX_MATCH_TASK_REPORT.pdf
A14: af05308442 | B14: TNDBS | C14: ANP-D7435 | D14: Mahalakshmi AK | E14: ak.mahaarul@gmail.com | F14: Graded | G14: 100 | H14: 95 | I14: Wednesday, 12 August 2026, 12:39 AM | J14: MAHALAKSHMI A K_LAB5.pdf
A15: af05308473 | B15: TNDBS | C15: ANP-D7435 | D15: Nikil Raja R | E15: nikilraja31@gmail.com | F15: Graded | G15: 100 | H15: 95 | I15: Wednesday, 12 August 2026, 12:51 AM | J15: Nikil Raja R Lab- 5.pdf
A16: af05308793 | B16: TNDBS | C16: ANP-D7435 | D16: Surya Narayanan Rameshbabu | E16: workpp2025may@gmail.com | F16: Graded | G16: 100 | H16: 95 | I16: Wednesday, 12 August 2026, 10:21 AM | J16: Surya Narayanan R LAB.docx
A17: af05308357 | B17: TNDBS | C17: ANP-D7435 | D17: Syed Sarferaz Sajid A | E17: sarferazsajid77@gmail.com | F17: Graded | G17: 100 | H17: 95 | I17: Wednesday, 12 August 2026, 10:38 AM | J17: TASK_5.pdf
A18: af05308374 | B18: TNDBS | C18: ANP-D7435 | D18: Lakshmikanthan G | E18: lakshug999@gmail.com | F18: Graded | G18: 100 | H18: 95 | I18: Wednesday, 12 August 2026, 11:42 AM | J18: lap 5.pdf
A19: af05309827 | B19: TNDBS | C19: ANP-D7435 | D19: Thamarai Selvan N | E19: thamaraiselvan358@gmail.com | F19: Graded | G19: 100 | H19: 95 | I19: Wednesday, 12 August 2026, 12:50 PM | J19: LAB-5.pdf
A20: af05310678 | B20: TNDBS | C20: ANP-D7435 | D20: Afrin M | E20: afu170798@gmail.com | F20: Graded | G20: 100 | H20: 95 | I20: Wednesday, 12 August 2026, 2:21 PM | J20: lab 5.pdf
A21: af05313450 | B21: TNDBS | C21: ANP-D7435 | D21: Mohamed Shahir Hussain G | E21: shahir.157igms@gmail.com | F21: Graded | G21: 100 | H21: 95 | I21: Wednesday, 12 August 2026, 2:54 PM | J21: TASK_5.docx
A22: af05308766 | B22: TNDBS | C22: ANP-D7435 | D22: Nithish G | E22: gtnithish2003@gmail.com | F22: Graded | G22: 100 | H22: 95 | I22: Wednesday, 12 August 2026, 3:04 PM | J22: Lab5-task.docx | K22: I Successfully Completed my Tas
A23: af05308359 | B23: TNDBS | C23: ANP-D7435 | D23: Sasidharan A | E23: sasidh9198@gmail.com | F23: Graded | G23: 100 | H23: 95 | I23: Wednesday, 12 August 2026, 6:22 PM | J23: LAB_5.pdf
A24: af05308373 | B24: TNDBS | C24: ANP-D7435 | D24: Sivaranjani T | E24: Sivaranjanithillai2010@gmail.com | F24: Graded | G24: 100 | H24: 95 | I24: Wednesday, 12 August 2026, 10:58 PM | J24: Lab6.pdf
A25: af05308381 | B25: TNDBS | C25: ANP-D7435 | D25: Aarthi R | E25: aarthirajaguru63@gmail.com | F25: Graded | G25: 100 | H25: 95 | I25: Wednesday, 12 August 2026, 10:59 PM | J25: AARTHI_R_EXCEL5.pdf
A26: af05308156 | B26: TNDBS | C26: ANP-D7435 | D26: Gowtham S | E26: gowthams2k20@gmail.com | F26: Graded | G26: 100 | H26: 95 | I26: Thursday, 13 August 2026, 8:49 AM | J26: TASK_5.pdf
A27: af05308383 | B27: TNDBS | C27: ANP-D7435 | D27: Yuvaraj M | E27: yuvayuvaraj331@gmail.com | F27: Graded | G27: 100 | H27: 95 | I27: Thursday, 13 August 2026, 11:28 AM | J27: Lab 5.pdf
A28: af05308382 | B28: TNDBS | C28: ANP-D7435 | D28: Harini M | E28: mharini0701@gmail.com | F28: Graded | G28: 100 | H28: 95 | I28: Thursday, 13 August 2026, 12:15 PM | J28: Harini_Lab_Task5.pdf
A29: af05308431 | B29: TNDBS | C29: ANP-D7435 | D29: Silvan S | E29: silvannathaniel@gmail.com | F29: Graded | G29: 100 | H29: 95 | I29: Thursday, 13 August 2026, 2:23 PM | J29: task-4.pdf
A30: af05313301 | B30: TNDBS | C30: ANP-D7435 | D30: Saravana Prabu V | E30: saravanaprabuv5@gmail.com | F30: Graded | G30: 100 | H30: 95 | I30: Thursday, 13 August 2026, 3:37 PM | J30: SARAVANA lab5.pdf
A31: af05309824 | B31: TNDBS | C31: ANP-D7435 | D31: Hariharan S | E31: hariharanst0203@gmail.com | F31: Graded | G31: 100 | H31: 95 | I31: Thursday, 13 August 2026, 9:01 PM | J31: Lab-5 Index + match.pdf
A32: af05309275 | B32: TNDBS | C32: ANP-D7435 | D32: Annett George | E32: georgeannette24@gmail.com | F32: Graded | G32: 100 | H32: 95 | I32: Friday, 14 August 2026, 10:26 AM | J32: task (1).docx
A33: af05308566 | B33: TNDBS | C33: ANP-D7435 | D33: Andrews Samuel A | E33: samuelandrews951@gmail.com | F33: Graded | G33: 100 | H33: 95 | I33: Tuesday, 18 August 2026, 3:56 PM | J33: Lab 5.pdf
A34: af05309754 | B34: TNDBS | C34: ANP-D7435 | D34: Harish B | E34: harishbalaji147@gmail.com | F34: Graded | G34: 100 | H34: 95 | I34: Tuesday, 18 August 2026, 4:03 PM | J34: Harish-Lab-5.pdf | K34: INDEX MATCH task (LAB-5)

Sheet Lab-4
A1: User ID | B1: Center Code | C1: Batch Code | D1: First Name/Surname | E1: Email | F1: Status | G1: Total Marks | H1: Marks | I1: Last modified (submission) | J1: File submission | K1: Online text
A2: af05308119 | B2: TNDBS | C2: ANP-D7435 | D2: Keerthikraj J | E2: jpkeerthik30@gmail.com | F2: Graded | G2: 100 | H2: 90 | I2: Tuesday, 11 August 2026, 4:41 PM | J2: V LOOKUP.pdf | K2: 🧾 Task Desc
A3: af05308512 | B3: TNDBS | C3: ANP-D7435 | D3: Sandra Sebastian | E3: sandrasebastian000@gmail.com | F3: Graded | G3: 100 | H3: 90 | I3: Tuesday, 11 August 2026, 5:13 PM | J3: task4.pdf
A4: af05310365 | B4: TNDBS | C4: ANP-D7435 | D4: Kishori J | E4: kishori200510@gmail.com | F4: Graded | G4: 100 | H4: 95 | I4: Tuesday, 11 August 2026, 5:24 PM | J4: LAB.pdf
A5: af05309665 | B5: TNDBS | C5: ANP-D7435 | D5: Jagadeeswary T | E5: jagadeeswary2006@gmail.com | F5: Graded | G5: 100 | H5: 93 | I5: Tuesday, 11 August 2026, 6:13 PM | J5: jaga_lab4 (1).pdf
A6: af05311479 | B6: TNDBS | C6: ANP-D7435 | D6: Pavithra S | E6: pavithrasekar1692003@gmail.com | F6: Graded | G6: 100 | H6: 95 | I6: Tuesday, 11 August 2026, 6:49 PM | J6: LMS 4 Vlookup.pdf
A7: af05308375 | B7: TNDBS | C7: ANP-D7435 | D7: Joe william A | E7: joewilliam147@gmail.com | F7: Graded | G7: 100 | H7: 90 | I7: Tuesday, 11 August 2026, 7:43 PM | J7: TASK_4.pdf
A8: af05309846 | B8: TNDBS | C8: ANP-D7435 | D8: Vansh Vijeynath B | E8: vanshvijeynath27@gmail.com | F8: Graded | G8: 100 | H8: 90 | I8: Tuesday, 11 August 2026, 7:48 PM | J8: Vansh Vijeynath B LAB 4.pdf
A9: af05308489 | B9: TNDBS | C9: ANP-D7435 | D9: Sandhiya M | E9: msandhiya124@gmail.com | F9: Graded | G9: 100 | H9: 90 | I9: Tuesday, 11 August 2026, 7:55 PM | J9: LAB 4.pdf | K9: I Have Completed my Lab 4 and S
A10: af05308376 | B10: TNDBS | C10: ANP-D7435 | D10: Satheesh Kumar G | E10: satheeshkumar14796@gmail.com | F10: Graded | G10: 100 | H10: 92 | I10: Tuesday, 11 August 2026, 8:17 PM | J10: Satheesh_Kumar_G-Lab-4.pdf | K10: Vlookup & Conditional Forma
A11: af05308992 | B11: TNDBS | C11: ANP-D7435 | D11: Santhosh Raj N | E11: santhoshjn11@gmail.com | F11: Graded | G11: 100 | H11: 90 | I11: Tuesday, 11 August 2026, 9:10 PM | J11: Insurance_Data.pdf
A12: af05308353 | B12: TNDBS | C12: ANP-D7435 | D12: Varshini A S | E12: varshinivela2309@gmail.com | F12: Submitted for evaluating | G12: 100 | I12: Tuesday, 11 August 2026, 9:37 PM | J12: Varshini Lab task 4.pdf
A13: af05308380 | B13: TNDBS | C13: ANP-D7435 | D13: Swathi S | E13: swathi.anitha127@gmail.com | F13: Graded | G13: 100 | H13: 96 | I13: Tuesday, 11 August 2026, 10:15 PM | J13: TASK4_LOOKUP_REPORT.pdf
A14: af05308473 | B14: TNDBS | C14: ANP-D7435 | D14: Nikil Raja R | E14: nikilraja31@gmail.com | F14: Graded | G14: 100 | H14: 96 | I14: Tuesday, 11 August 2026, 11:35 PM | J14: Nikil Raja R Lab-4.pdf
A15: af05308442 | B15: TNDBS | C15: ANP-D7435 | D15: Mahalakshmi AK | E15: ak.mahaarul@gmail.com | F15: Graded | G15: 100 | H15: 95 | I15: Tuesday, 11 August 2026, 11:36 PM | J15: MAHALAKSHMI A K_LAB4.pdf
A16: af05308431 | B16: TNDBS | C16: ANP-D7435 | D16: Silvan S | E16: silvannathaniel@gmail.com | F16: Graded | G16: 100 | H16: 90 | I16: Tuesday, 11 August 2026, 11:54 PM | J16: task-4 Silvan.pdf
A17: af05308793 | B17: TNDBS | C17: ANP-D7435 | D17: Surya Narayanan Rameshbabu | E17: workpp2025may@gmail.com | F17: Graded | G17: 100 | H17: 90 | I17: Wednesday, 12 August 2026, 9:56 AM | J17: Surya Narayanan R LAB.docx
A18: af05308357 | B18: TNDBS | C18: ANP-D7435 | D18: Syed Sarferaz Sajid A | E18: sarferazsajid77@gmail.com | F18: Graded | G18: 100 | H18: 90 | I18: Wednesday, 12 August 2026, 10:37 AM | J18: TASK_4.pdf
A19: af05308374 | B19: TNDBS | C19: ANP-D7435 | D19: Lakshmikanthan G | E19: lakshug999@gmail.com | F19: Graded | G19: 100 | H19: 90 | I19: Wednesday, 12 August 2026, 12:42 PM | J19: lap 4.pdf
A20: af05309827 | B20: TNDBS | C20: ANP-D7435 | D20: Thamarai Selvan N | E20: thamaraiselvan358@gmail.com | F20: Graded | G20: 100 | H20: 95 | I20: Wednesday, 12 August 2026, 12:48 PM | J20: LAB_4.pdf
A21: af05310678 | B21: TNDBS | C21: ANP-D7435 | D21: Afrin M | E21: afu170798@gmail.com | F21: Graded | G21: 100 | H21: 95 | I21: Wednesday, 12 August 2026, 12:49 PM | J21: lab 4.pdf
A22: af05313450 | B22: TNDBS | C22: ANP-D7435 | D22: Mohamed Shahir Hussain G | E22: shahir.157igms@gmail.com | F22: Graded | G22: 100 | H22: 95 | I22: Wednesday, 12 August 2026, 2:53 PM | J22: TASK_4.docx
A23: af05308766 | B23: TNDBS | C23: ANP-D7435 | D23: Nithish G | E23: gtnithish2003@gmail.com | F23: Graded | G23: 100 | H23: 95 | I23: Wednesday, 12 August 2026, 3:03 PM | J23: lab4-task.docx | K23: I Successfully Completed this T
A24: af05309754 | B24: TNDBS | C24: ANP-D7435 | D24: Harish B | E24: harishbalaji147@gmail.com | F24: Graded | G24: 100 | H24: 95 | I24: Wednesday, 12 August 2026, 5:01 PM | J24: Harish-lab-4.pdf | K24: LOOK UP and IF ERROR
A25: af05308359 | B25: TNDBS | C25: ANP-D7435 | D25: Sasidharan A | E25: sasidh9198@gmail.com | F25: Graded | G25: 100 | H25: 95 | I25: Wednesday, 12 August 2026, 6:22 PM | J25: LAB_4.pdf
A26: af05308373 | B26: TNDBS | C26: ANP-D7435 | D26: Sivaranjani T | E26: Sivaranjanithillai2010@gmail.com | F26: Graded | G26: 100 | H26: 95 | I26: Wednesday, 12 August 2026, 10:57 PM | J26: Lab 5.pdf
A27: af05308381 | B27: TNDBS | C27: ANP-D7435 | D27: Aarthi R | E27: aarthirajaguru63@gmail.com | F27: Graded | G27: 100 | H27: 95 | I27: Wednesday, 12 August 2026, 10:58 PM | J27: AARTHI_R_EXCEL4.pdf
A28: af05308156 | B28: TNDBS | C28: ANP-D7435 | D28: Gowtham S | E28: gowthams2k20@gmail.com | F28: Graded | G28: 100 | H28: 95 | I28: Thursday, 13 August 2026, 8:43 AM | J28: TASK_4.pdf
A29: af05308383 | B29: TNDBS | C29: ANP-D7435 | D29: Yuvaraj M | E29: yuvayuvaraj331@gmail.com | F29: Graded | G29: 100 | H29: 95 | I29: Thursday, 13 August 2026, 11:15 AM | J29: Task 4.pdf
A30: af05308382 | B30: TNDBS | C30: ANP-D7435 | D30: Harini M | E30: mharini0701@gmail.com | F30: Graded | G30: 100 | H30: 95 | I30: Thursday, 13 August 2026, 3:11 PM | J30: Harini_Lab_Task4.pdf
A31: af05313301 | B31: TNDBS | C31: ANP-D7435 | D31: Saravana Prabu V | E31: saravanaprabuv5@gmail.com | F31: Graded | G31: 100 | H31: 95 | I31: Thursday, 13 August 2026, 3:36 PM | J31: SARAVANA lab4.pdf
A32: af05309824 | B32: TNDBS | C32: ANP-D7435 | D32: Hariharan S | E32: hariharanst0203@gmail.com | F32: Graded | G32: 100 | H32: 96 | I32: Thursday, 13 August 2026, 11:06 PM | J32: Lab 4- Lookup Function .pdf
A33: af05309275 | B33: TNDBS | C33: ANP-D7435 | D33: Annett George | E33: georgeannette24@gmail.com | F33: Graded | G33: 100 | H33: 95 | I33: Friday, 14 August 2026, 9:56 AM | J33: task-5.docx
A34: af05308566 | B34: TNDBS | C34: ANP-D7435 | D34: Andrews Samuel A | E34: samuelandrews951@gmail.com | F34: Graded | G34: 100 | H34: 95 | I34: Tuesday, 18 August 2026, 3:55 PM | J34: task 4.pdf

Sheet Lab-3
A1: User ID | B1: Center Code | C1: Batch Code | D1: First Name/Surname | E1: Email | F1: Status | G1: Total Marks | H1: Marks | I1: Last modified (submission) | J1: File submission | K1: Online text
A2: af05308793 | B2: TNDBS | C2: ANP-D7435 | D2: Surya Narayanan Rameshbabu | E2: workpp2025may@gmail.com | F2: Graded | G2: 100 | H2: 90 | I2: Thursday, 6 August 2026, 5:19 PM | J2: Surya Narayanan R LAB.docx
A3: af05310365 | B3: TNDBS | C3: ANP-D7435 | D3: Kishori J | E3: kishori200510@gmail.com | F3: Graded | G3: 100 | H3: 90 | I3: Thursday, 6 August 2026, 5:42 PM | J3: KISHORI_LAB3.pdf
A4: af05311479 | B4: TNDBS | C4: ANP-D7435 | D4: Pavithra S | E4: pavithrasekar1692003@gmail.com | F4: Graded | G4: 100 | H4: 95 | I4: Thursday, 6 August 2026, 6:37 PM | J4: Excel 3 LMS.pdf
A5: af05308512 | B5: TNDBS | C5: ANP-D7435 | D5: Sandra Sebastian | E5: sandrasebastian000@gmail.com | F5: Graded | G5: 100 | H5: 95 | I5: Thursday, 6 August 2026, 6:55 PM | J5: task3.pdf
A6: af05308489 | B6: TNDBS | C6: ANP-D7435 | D6: Sandhiya M | E6: msandhiya124@gmail.com | F6: Graded | G6: 100 | H6: 95 | I6: Thursday, 6 August 2026, 8:28 PM | J6: Lab 3.pdf | K6: I have completed my Lab3 and submitted for evaluating
A7: af05308992 | B7: TNDBS | C7: ANP-D7435 | D7: Santhosh Raj N | E7: santhoshjn11@gmail.com | F7: Graded | G7: 100 | H7: 95 | I7: Thursday, 6 August 2026, 8:43 PM | J7: excel lab-3.pdf
A8: af05309275 | B8: TNDBS | C8: ANP-D7435 | D8: Annett George | E8: georgeannette24@gmail.com | F8: Graded | G8: 100 | H8: 90 | I8: Thursday, 6 August 2026, 8:47 PM | J8: Lab-3.docx
A9: af05308373 | B9: TNDBS | C9: ANP-D7435 | D9: Sivaranjani T | E9: Sivaranjanithillai2010@gmail.com | F9: Graded | G9: 100 | H9: 96 | I9: Thursday, 6 August 2026, 10:36 PM | J9: sivaranjani T Lab3.pdf
A10: af05308381 | B10: TNDBS | C10: ANP-D7435 | D10: Aarthi R | E10: aarthirajaguru63@gmail.com | F10: Graded | G10: 100 | H10: 96 | I10: Thursday, 6 August 2026, 10:45 PM | J10: AARTHI_R_EXCEL3.pdf
A11: af05308380 | B11: TNDBS | C11: ANP-D7435 | D11: Swathi S | E11: swathi.anitha127@gmail.com | F11: Graded | G11: 100 | H11: 98 | I11: Thursday, 6 August 2026, 11:08 PM | J11: Professional_Conditional_Formatting_Task_3_v2.pdf
A12: af05309824 | B12: TNDBS | C12: ANP-D7435 | D12: Hariharan S | E12: hariharanst0203@gmail.com | F12: Graded | G12: 100 | H12: 96 | I12: Friday, 7 August 2026, 9:48 AM | J12: Lab 3 Conditional formatting Reference .pdf
A13: af05308376 | B13: TNDBS | C13: ANP-D7435 | D13: Satheesh Kumar G | E13: satheeshkumar14796@gmail.com | F13: Graded | G13: 100 | H13: 98 | I13: Friday, 7 August 2026, 11:37 AM | J13: Satheesh_Kumar_G-Lab-3.pdf | K13: Conditional Formatting
A14: af05308156 | B14: TNDBS | C14: ANP-D7435 | D14: Gowtham S | E14: gowthams2k20@gmail.com | F14: Graded | G14: 100 | H14: 95 | I14: Friday, 7 August 2026, 11:54 AM | J14: excel3.pdf
A15: af05308357 | B15: TNDBS | C15: ANP-D7435 | D15: Syed Sarferaz Sajid A | E15: sarferazsajid77@gmail.com | F15: Graded | G15: 100 | H15: 96 | I15: Friday, 7 August 2026, 12:26 PM | J15: Task 3 CONDITIONAL FORMATING.pdf
A16: af05308353 | B16: TNDBS | C16: ANP-D7435 | D16: Varshini A S | E16: varshinivela2309@gmail.com | F16: Graded | G16: 100 | H16: 95 | I16: Friday, 7 August 2026, 12:36 PM | J16: Varshini lab Task -3.pdf
A17: af05309827 | B17: TNDBS | C17: ANP-D7435 | D17: Thamarai Selvan N | E17: thamaraiselvan358@gmail.com | F17: Graded | G17: 100 | H17: 95 | I17: Friday, 7 August 2026, 12:52 PM | J17: Lab-3.pdf
A18: af05309754 | B18: TNDBS | C18: ANP-D7435 | D18: Harish B | E18: harishbalaji147@gmail.com | F18: Graded | G18: 100 | H18: 80 | I18: Friday, 7 August 2026, 2:59 PM | J18: Harish-lab-3.pdf
A19: af05308375 | B19: TNDBS | C19: ANP-D7435 | D19: Joe william A | E19: joewilliam147@gmail.com | F19: Graded | G19: 100 | H19: 95 | I19: Friday, 7 August 2026, 3:02 PM | J19: TASK_3.pdf
A20: af05308382 | B20: TNDBS | C20: ANP-D7435 | D20: Harini M | E20: mharini0701@gmail.com | F20: Graded | G20: 100 | H20: 95 | I20: Friday, 7 August 2026, 3:11 PM | J20: Harini_Lab_Task3.pdf
A21: af05308442 | B21: TNDBS | C21: ANP-D7435 | D21: Mahalakshmi AK | E21: ak.mahaarul@gmail.com | F21: Graded | G21: 100 | H21: 90 | I21: Friday, 7 August 2026, 3:12 PM | J21: MAHALAKSHMI A K_LAB3.pdf
A22: af05308359 | B22: TNDBS | C22: ANP-D7435 | D22: Sasidharan A | E22: sasidh9198@gmail.com | F22: Graded | G22: 100 | H22: 95 | I22: Friday, 7 August 2026, 3:13 PM | J22: CONDITIONAL FORMATING.pdf
A23: af05308119 | B23: TNDBS | C23: ANP-D7435 | D23: Keerthikraj J | E23: jpkeerthik30@gmail.com | F23: Graded | G23: 100 | H23: 95 | I23: Friday, 7 August 2026, 3:56 PM | J23: Coniditional Formatting. Lab3.pdf
A24: af05313301 | B24: TNDBS | C24: ANP-D7435 | D24: Saravana Prabu V | E24: saravanaprabuv5@gmail.com | F24: Graded | G24: 100 | H24: 95 | I24: Friday, 7 August 2026, 4:05 PM | J24: Lab Title 4.pdf
A25: af05309846 | B25: TNDBS | C25: ANP-D7435 | D25: Vansh Vijeynath B | E25: vanshvijeynath27@gmail.com | F25: Graded | G25: 100 | H25: 95 | I25: Friday, 7 August 2026, 4:05 PM | J25: Vansh Vijeynath B LAB 3.pdf
... A29: af05308431 | B29: TNDBS | C29: ANP-D7435 | D29: Silvan S | E29: silvannathaniel@gmail.com | F29: Graded | G29: 100 | H29: 95 | I29: Friday, 7 August 2026, 11:51 PM | J29: Lab-3.pdf
A30: af05308766 | B30: TNDBS | C30: ANP-D7435 | D30: Nithish G | E30: gtnithish2003@gmail.com | F30: Graded | G30: 100 | H30: 95 | I30: Friday, 7 August 2026, 11:51 PM | J30: I Finished LAB3 task assignment .pdf | K30: I Finished my LAB3- task assign
A31: af05310678 | B31: TNDBS | C31: ANP-D7435 | D31: Afrin M | E31: afu170798@gmail.com | F31: Graded | G31: 100 | H31: 90 | I31: Sunday, 9 August 2026, 3:31 PM | J31: Lab 3.pdf
A32: af05308566 | B32: TNDBS | C32: ANP-D7435 | D32: Andrews Samuel A | E32: samuelandrews951@gmail.com | F32: Graded | G32: 100 | H32: 95 | I32: Sunday, 9 August 2026, 7:05 PM | J32: Andrew (1).pdf
A33: af05308374 | B33: TNDBS | C33: ANP-D7435 | D33: Lakshmikanthan G | E33: lakshug999@gmail.com | F33: Graded | G33: 100 | H33: 90 | I33: Monday, 10 August 2026, 2:52 PM | J33: lap 3.pdf
A34: af05313450 | B34: TNDBS | C34: ANP-D7435 | D34: Mohamed Shahir Hussain G | E34: shahir.157igms@gmail.com | F34: Graded | G34: 100 | H34: 90 | I34: Tuesday, 11 August 2026, 8:00 PM | J34: task3.docx

Sheet Lab-2
A1: User ID | B1: Center Code | C1: Batch Code | D1: First Name/Surname | E1: Email | F1: Status | G1: Total Marks | H1: Marks | I1: Last modified (submission) | J1: File submission | K1: Online text
A2: af05309275 | B2: TNDBS | C2: ANP-D7435 | D2: Annett George | E2: georgeannette24@gmail.com | F2: Graded | G2: 100 | H2: 98 | I2: Tuesday, 4 August 2026, 4:56 PM | J2: Lab 2.docx
A3: af05308793 | B3: TNDBS | C3: ANP-D7435 | D3: Surya Narayanan Rameshbabu | E3: workpp2025may@gmail.com | F3: Graded | G3: 100 | H3: 98 | I3: Tuesday, 4 August 2026, 4:56 PM | J3: Surya Narayanan R LAB.docx
A4: af05308119 | B4: TNDBS | C4: ANP-D7435 | D4: Keerthikraj J | E4: jpkeerthik30@gmail.com | F4: Graded | G4: 100 | H4: 97 | I4: Tuesday, 4 August 2026, 5:14 PM | J4: Keerthik.Lab 2.pdf | K4: Summary Report
A5: af05308512 | B5: TNDBS | C5: ANP-D7435 | D5: Sandra Sebastian | E5: sandrasebastian000@gmail.com | F5: Graded | G5: 100 | H5: 98 | I5: Tuesday, 4 August 2026, 5:20 PM | J5: task2.pdf
A6: af05310365 | B6: TNDBS | C6: ANP-D7435 | D6: Kishori J | E6: kishori200510@gmail.com | F6: Graded | G6: 100 | H6: 98 | I6: Tuesday, 4 August 2026, 5:33 PM | J6: lab2_kishori.docx
A7: af05308376 | B7: TNDBS | C7: ANP-D7435 | D7: Satheesh Kumar G | E7: satheeshkumar14796@gmail.com | F7: Graded | G7: 100 | H7: 98 | I7: Tuesday, 4 August 2026, 8:00 PM | J7: Satheesh_Kumar_G-Lab-2.pdf | K7: Aggregations like Sum, Sumif, S
A8: af05308992 | B8: TNDBS | C8: ANP-D7435 | D8: Santhosh Raj N | E8: santhoshjn11@gmail.com | F8: Graded | G8: 100 | H8: 98 | I8: Tuesday, 4 August 2026, 8:16 PM | J8: Logical_Functions_SUM_COUNT_Practice.pdf
A9: af05308373 | B9: TNDBS | C9: ANP-D7435 | D9: Sivaranjani T | E9: Sivaranjanithillai2010@gmail.com | F9: Graded | G9: 100 | H9: 98 | I9: Tuesday, 4 August 2026, 9:50 PM | J9: Sivaranjani T Lab2.docx
A10: af05308473 | B10: TNDBS | C10: ANP-D7435 | D10: Nikil Raja R | E10: nikilraja31@gmail.com | F10: Graded | G10: 100 | H10: 97 | I10: Tuesday, 4 August 2026, 10:49 PM | J10: Nikil Raja Lab-2.pdf
A11: af05308442 | B11: TNDBS | C11: ANP-D7435 | D11: Mahalakshmi AK | E11: ak.mahaarul@gmail.com | F11: Graded | G11: 100 | H11: 96 | I11: Tuesday, 4 August 2026, 10:50 PM | J11: MAHALAKSHMI A K_LAB2.pdf
A12: af05308381 | B12: TNDBS | C12: ANP-D7435 | D12: Aarthi R | E12: aarthirajaguru63@gmail.com | F12: Graded | G12: 100 | H12: 98 | I12: Tuesday, 4 August 2026, 10:52 PM | J12: AARTHI_R_EXCEL2.pdf
A13: af05308375 | B13: TNDBS | C13: ANP-D7435 | D13: Joe william A | E13: joewilliam147@gmail.com | F13: Graded | G13: 100 | H13: 98 | I13: Wednesday, 5 August 2026, 9:42 AM | J13: TASK2.pdf
A14: af05308156 | B14: TNDBS | C14: ANP-D7435 | D14: Gowtham S | E14: gowthams2k20@gmail.com | F14: Graded | G14: 100 | H14: 98 | I14: Wednesday, 5 August 2026, 9:46 AM | J14: excel2.pdf
A15: af05308357 | B15: TNDBS | C15: ANP-D7435 | D15: Syed Sarferaz Sajid A | E15: sarferazsajid77@gmail.com | F15: Graded | G15: 100 | H15: 98 | I15: Wednesday, 5 August 2026, 10:19 AM | J15: Logical Function using Sum and Count (Task 2).pdf
A16: af05308380 | B16: TNDBS | C16: ANP-D7435 | D16: Swathi S | E16: swathi.anitha127@gmail.com | F16: Graded | G16: 100 | H16: 98 | I16: Wednesday, 5 August 2026, 10:59 AM | J16: task2pdf.pdf
A17: af05313301 | B17: TNDBS | C17: ANP-D7435 | D17: Saravana Prabu V | E17: saravanaprabuv5@gmail.com | F17: Graded | G17: 100 | H17: 98 | I17: Wednesday, 5 August 2026, 11:27 AM | J17: saravana.pdf
A18: af05309846 | B18: TNDBS | C18: ANP-D7435 | D18: Vansh Vijeynath B | E18: vanshvijeynath27@gmail.com | F18: Graded | G18: 100 | H18: 98 | I18: Wednesday, 5 August 2026, 12:12 PM | J18: Vansh Vijeynath B LAB 2.pdf | K18: Mam all three condition formula
A19: af05311479 | B19: TNDBS | C19: ANP-D7435 | D19: Pavithra S | E19: pavithrasekar1692003@gmail.com | F19: Graded | G19: 100 | H19: 98 | I19: Wednesday, 5 August 2026, 1:03 PM | J19: LMS 2.pdf
A20: af05310678 | B20: TNDBS | C20: ANP-D7435 | D20: Afrin M | E20: afu170798@gmail.com | F20: Graded | G20: 100 | H20: 98 | I20: Wednesday, 5 August 2026, 1:29 PM | J20: lab 2 sumif.pdf
